##  git 合并远程仓库分支

- git pull

  拉去远程库所有情况（包括分支

  $ git pull
  Already up to date.

- git branch -a

  可以看到把远程分支拉过来了

  $ git branch -a

  - master
    remotes/origin/com
    remotes/origin/master

- git merge origin/com

  合并分支

  $ git merge origin/com
  CONFLICT (add/add): Merge conflict in src/priv/wzb/leet_code/dynamic_programming/interleaving_string_97/Solution1.java
  Auto-merging src/priv/wzb/leet_code/dynamic_programming/interleaving_string_97/Solution1.java
  Automatic merge failed; fix conflicts and then commit the result.

  有冲突，可以且到IDE进行剞劂

- git add .

  提交所有文件

- git commit -m "msg"

  提交merge

  可以看到状态从master|MERGING变为master

  ![1597671247715](C:\Users\DELL\AppData\Roaming\Typora\typora-user-images\1597671247715.png)

- 提交到远程

  git push origin master

## 自定义异常

从最近的异常类继承定义异常

使用日志打印异常

## 异常声明

告知客户端程序员可能会出现什么异常

## 捕获所有异常

```java
catch(Exception e) {
    System.out.println("Caught an exception");
}
```

可捕获所有异常但是太宽泛可以放在最后捕获，月前面的异常越接近真正的错误细节

## 多重捕获

```java
// exceptions/SameHandler.java
class EBase1 extends Exception {}
class Except1 extends EBase1 {}
class EBase2 extends Exception {}
class Except2 extends EBase2 {}
class EBase3 extends Exception {}
class Except3 extends EBase3 {}
class EBase4 extends Exception {}
class Except4 extends EBase4 {}

public class SameHandler {
    void x() throws Except1, Except2, Except3, Except4 {}
    void process() {}
    void f() {
        try {
            x();
        } catch(Except1 e) {
            process();
        } catch(Except2 e) {
            process();
        } catch(Except3 e) {
            process();
        } catch(Except4 e) {
            process();
        }
    }
}
```

使用或

```java
// exceptions/MultiCatch.java
public class MultiCatch {
    void x() throws Except1, Except2, Except3, Except4 {}
    void process() {}
    void f() {
        try {
            x();
        } catch(Except1 | Except2 | Except3 | Except4 e) {
            process();
        }
    }
}
```

## 栈轨迹

e.printStackTrace

StackTrace可以通过getStackTrace()来访问

Java标准一场

Throwable是所有异常基类

下面分为

- Error

  编译时和系统错误，无需关心

- Exception

  可以被抛出的异常，主要关心的异常类型



特例 RuntimeException

```java
if(t == null)
    throw new NullPointerException();
```

duck不必

运行时调用null的引用会抛出NullPointerException

属于运行时异常的类型有很多，他们被Java自动抛出，所以不必在异常说明中列出他们。所以运行时异常都是RuntimeException的子类

RuntimeExcpetion代表的是编程错误：

1. 无法预料的错误。比如从你控制范围之外传递进来的null引用
2. 作为programmer应该在代码中进行检查的错误。异常发生在一个地方让另一个地方抛出

## 使用finally进行清理

```java
try {
// The guarded region: Dangerous activities
// that might throw A, B, or C
} catch(A a1) {
// Handler for situation A
} catch(B b1) {
// Handler for situation B
} catch(C c1) {
// Handler for situation C
} finally {
// Activities that happen every time
}
```

不管异常是否被抛出finally都会执行。

即使调用return

清理外部资源会导初始就可以用finally

```java
// exceptions/WithFinally.java
// Finally Guarantees cleanup
public class WithFinally {
    static Switch sw = new Switch();
    public static void main(String[] args) {
        try {
            sw.on();
            // Code that can throw exceptions...
            OnOffSwitch.f();
        } catch(OnOffException1 e) {
            System.out.println("OnOffException1");
        } catch(OnOffException2 e) {
            System.out.println("OnOffException2");
        } finally {
            sw.off();
        }
    }
}

```

## 异常缺失

调用finally就会造成异常缺失

```java
// exceptions/LostMessage.java
// How an exception can be lost
class VeryImportantException extends Exception {
    @Override
    public String toString() {
        return "A very important exception!";
    }
}
class HoHumException extends Exception {
    @Override
    public String toString() {
        return "A trivial exception";
    }
}
public class LostMessage {
    void f() throws VeryImportantException {
        throw new VeryImportantException();
    }
    void dispose() throws HoHumException {
        throw new HoHumException();
    }
    public static void main(String[] args) {
        try {
            LostMessage lm = new LostMessage();
            try {
                lm.f();
            } finally {
                lm.dispose();
            }
        } catch(VeryImportantException | HoHumException e) {
            System.out.println(e);
        }
    }
}
```

输出

```
A trivial exception
```

finally+返回

```java
// exceptions/ExceptionSilencer.java
public class ExceptionSilencer {
    public static void main(String[] args) {
        try {
            throw new RuntimeException();
        } finally {
            // Using 'return' inside the finally block
            // will silence any thrown exception.
            return;
        }
    }
}
```

导致即使抛出也看不到任何输出

## 异常限制



尽管在继承过程中，编译器会对异常说明做强制要求，但异常说明本身并不属于方法类型的一部分，方法类型是由方法的名字与参数的类型组成的。因此，不能基于异常说明来重载方法。此外，一个出现在基类方法的异常说明中的异常，不一定会出现在派生类方法的异常说明里。这点同继承的规则明显不同，在继承中，基类的方法必须出现在派生类里，换句话说，在继承和覆盖的过程中，某个特定方法的“异常说明的接口”不是变大了而是变小了——这恰好和类接口在继承时的情形相反。

## 构造器

```java
// exceptions/InputFile.java
// Paying attention to exceptions in constructors
import java.io.*;
public class InputFile {
    private BufferedReader in;
    public InputFile(String fname) throws Exception {
        try {
            in = new BufferedReader(new FileReader(fname));
            // Other code that might throw exceptions
        } catch(FileNotFoundException e) {
            System.out.println("Could not open " + fname);
            // Wasn't open, so don't close it
            throw e;
        } catch(Exception e) {
            // All other exceptions must close it
            try {
                in.close();
            } catch(IOException e2) {
                System.out.println("in.close() unsuccessful");
            }
            throw e; // Rethrow
        } finally {
        // Don't close it here!!!
        }
    }
    public String getLine() {
        String s;
        try {
            s = in.readLine();
        } catch(IOException e) {
            throw new RuntimeException("readLine() failed");
        }
        return s;
    }
    public void dispose() {
        try {
            in.close();
            System.out.println("dispose() successful");
        } catch(IOException e2) {
            throw new RuntimeException("in.close() failed");
        }
    }
}
```

finally如果关闭那么构造打开的文件就会失效整个类失去意义

```java
// exceptions/Cleanup.java
// Guaranteeing proper cleanup of a resource
public class Cleanup {
    public static void main(String[] args) {
        try {
            InputFile in = new InputFile("Cleanup.java");
            try {
                String s;
                int i = 1;
                while((s = in.getLine()) != null)
                    ; // Perform line-by-line processing here...
            } catch(Exception e) {
                System.out.println("Caught Exception in main");
                e.printStackTrace(System.out);
            } finally {
                in.dispose();
            }
        } catch(Exception e) {
            System.out.println(
                    "InputFile construction failed");
        }
    }
}
```

请仔细观察这里的逻辑：对 InputFile 对象的构造在其自己的 try 语句块中有效，如果构造失败，将进入外部的 catch 子句，而 dispose() 方法不会被调用。但是，如果构造成功，我们肯定想确保对象能够被清理，因此在构造之后立即创建了一个新的 try 语句块。执行清理的 finally 与内部的 try 语句块相关联。在这种方式中，finally 子句在构造失败时是不会执行的，而在构造成功时将总是执行。

这种通用的清理惯用法在构造器不抛出任何异常时也应该运用，其基本规则是：在创建需要清理的对象之后，立即进入一个 try-finally 语句

```java
// exceptions/CleanupIdiom.java
// Disposable objects must be followed by a try-finally
class NeedsCleanup { // Construction can't fail
    private static long counter = 1;
    private final long id = counter++;
    public void dispose() {
        System.out.println(
                "NeedsCleanup " + id + " disposed");
    }
}
class ConstructionException extends Exception {}
class NeedsCleanup2 extends NeedsCleanup {
    // Construction can fail:
    NeedsCleanup2() throws ConstructionException {}
}
public class CleanupIdiom {
    public static void main(String[] args) {
        // [1]:
        NeedsCleanup nc1 = new NeedsCleanup();
        try {
        // ...
        } finally {
            nc1.dispose();
        }
        // [2]:
        // If construction cannot fail,
        // you can group objects:
        NeedsCleanup nc2 = new NeedsCleanup();
        NeedsCleanup nc3 = new NeedsCleanup();
        try {
        // ...
        } finally {
            nc3.dispose(); // Reverse order of construction
            nc2.dispose();
        }
        // [3]:
        // If construction can fail you must guard each one:
        try {
            NeedsCleanup2 nc4 = new NeedsCleanup2();
            try {
                NeedsCleanup2 nc5 = new NeedsCleanup2();
                try {
                // ...
                } finally {
                    nc5.dispose();
                }
            } catch(ConstructionException e) { // nc5 const.
                System.out.println(e);
            } finally {
                nc4.dispose();
            }
        } catch(ConstructionException e) { // nc4 const.
            System.out.println(e);
        }
    }
}
```

##  try-with-resources 

捕获关闭异常

```java

// exceptions/MessyExceptions.java
import java.io.*;
public class MessyExceptions {
    public static void main(String[] args) {
        InputStream in = null;
        try {
            in = new FileInputStream(
                    new File("MessyExceptions.java"));
            int contents = in.read();
            // Process contents
        } catch(IOException e) {
            // Handle the error
        } finally {
            if(in != null) {
                try {
                    in.close();
                } catch(IOException e) {
                    // Handle the close() error
                }
            }
        }
    }
}
```

简化

```java
// exceptions/TryWithResources.java
import java.io.*;
public class TryWithResources {
    public static void main(String[] args) {
        try(
                InputStream in = new FileInputStream(
                        new File("TryWithResources.java"))
        ) {
            int contents = in.read();
            // Process contents
        } catch(IOException e) {
            // Handle the error
        }
    }
}
```

继承closeable的类可以通过try-with-resources来简化代码

```java
// exceptions/StreamsAreAutoCloseable.java
import java.io.*;
import java.nio.file.*;
import java.util.stream.*;
public class StreamsAreAutoCloseable {
    public static void
    main(String[] args) throws IOException{
        try(
                Stream<String> in = Files.lines(
                        Paths.get("StreamsAreAutoCloseable.java"));
                PrintWriter outfile = new PrintWriter(
                        "Results.txt"); // [1]
        ) {
            in.skip(5)
                    .limit(1)
                    .map(String::toLowerCase)
                    .forEachOrdered(outfile::println);
        } // [2]
    }
}
```

## 细节

```java
// exceptions/AutoCloseableDetails.java
class Reporter implements AutoCloseable {
    String name = getClass().getSimpleName();
    Reporter() {
        System.out.println("Creating " + name);
    }
    public void close() {
        System.out.println("Closing " + name);
    }
}
class First extends Reporter {}
class Second extends Reporter {}
public class AutoCloseableDetails {
    public static void main(String[] args) {
        try(
                First f = new First();
                Second s = new Second()
        ) {
        }
    }
}
```

```
Creating First
Creating Second
Closing Second
Closing First
```

## 匹配

自动匹配最接近的异常对象

```java
// exceptions/Human.java
// Catching exception hierarchies
class Annoyance extends Exception {}
class Sneeze extends Annoyance {}
public class Human {
    public static void main(String[] args) {
        // Catch the exact type:
        try {
            throw new Sneeze();
        } catch(Sneeze s) {
            System.out.println("Caught Sneeze");
        } catch(Annoyance a) {
            System.out.println("Caught Annoyance");
        }
        // Catch the base type:
        try {
            throw new Sneeze();
        } catch(Annoyance a) {
            System.out.println("Caught Annoyance");
        }
    }
}
```

```java
Caught Sneeze
Caught Annoyance
```

## 其他可选方式

异常处理的原则：只有知道如何处理才捕获异常。开发一场处理的初中是为了方便程序员处理错误。

分离错误处理与正常逻辑代码

“仅从小程序来看，会认为异常说明能增加开发人员的效率，并提高代码的质量；但考察大项目的时候，结论就不同了-开发效率下降了，而代码质量只有微不足道的提高，甚至毫无提高”。

## 异常指南

1. 尽可能使用 try-with-resource。
2. 在恰当的级别处理问题。（在知道该如何处理的情况下才捕获异常。）
3. 解决问题并且重新调用产生异常的方法。
4. 进行少许修补，然后绕过异常发生的地方继续执行。
5. 用别的数据进行计算，以代替方法预计会返回的值。
6. 把当前运行环境下能做的事情尽量做完，然后把相同的异常重抛到更高层。
7. 把当前运行环境下能做的事情尽量做完，然后把不同的异常抛到更高层。
8. 终止程序。
9. 进行简化。（如果你的异常模式使问题变得太复杂，那用起来会非常痛苦也很烦人。）
10. 让类库和程序更安全。（这既是在为调试做短期投资，也是在为程序的健壮性做长期投资。）

## 小结

异常是 Java 程序设计不可分割的一部分，如果不了解如何使用它们，那你只能完成很有限的工作。正因为如此，本书专门在此介绍了异常——对于许多类库（例如提到过的 I/O 库），如果不处理异常，你就无法使用它们。

异常处理的优点之一就是它使得你可以在某处集中精力处理你要解决的问题，而在另一处处理你编写的这段代码中产生的错误。尽管异常通常被认为是一种工具，使得你可以在运行时报告错误并从错误中恢复，但是我一直怀疑到底有多少时候“恢复”真正得以实现了，或者能够得以实现。我认为这种情况少于 10%，并且即便是这 10%，也只是将栈展开到某个已知的稳定状态，而并没有实际执行任何种类的恢复性行为。无论这是否正确，我一直相信“报告”功能是异常的精髓所在. Java 坚定地强调将所有的错误都以异常形式报告的这一事实，正是它远远超过如 C++ 这类语言的长处之一，因为在 C++ 这类语言中，需要以大量不同的方式来报告错误，或者根本就没有提供错误报告功能。一致的错误报告系统意味着，你再也不必对所写的每一段代码，都质问自己“错误是否正在成为漏网之鱼？”（只要你没有“吞咽”异常，这是关键所在！）。

就像你将要在后续章节中看到的，通过将这个问题甩给其他代码-即使你是通过抛出 RuntimeException 来实现这一点的--你在设计和实现时，便可以专注于更加有趣和富有挑战性的问题了。